Traceback (most recent call last):
  File "/home/grabow/anaconda3/envs/jb/lib/python3.10/site-packages/jupyter_cache/executors/utils.py", line 51, in single_nb_execution
    executenb(
  File "/home/grabow/anaconda3/envs/jb/lib/python3.10/site-packages/nbclient/client.py", line 1204, in execute
    return NotebookClient(nb=nb, resources=resources, km=km, **kwargs).execute()
  File "/home/grabow/anaconda3/envs/jb/lib/python3.10/site-packages/nbclient/util.py", line 84, in wrapped
    return just_run(coro(*args, **kwargs))
  File "/home/grabow/anaconda3/envs/jb/lib/python3.10/site-packages/nbclient/util.py", line 62, in just_run
    return loop.run_until_complete(coro)
  File "/home/grabow/anaconda3/envs/jb/lib/python3.10/asyncio/base_events.py", line 646, in run_until_complete
    return future.result()
  File "/home/grabow/anaconda3/envs/jb/lib/python3.10/site-packages/nbclient/client.py", line 663, in async_execute
    await self.async_execute_cell(
  File "/home/grabow/anaconda3/envs/jb/lib/python3.10/site-packages/nbclient/client.py", line 965, in async_execute_cell
    await self._check_raise_for_error(cell, cell_index, exec_reply)
  File "/home/grabow/anaconda3/envs/jb/lib/python3.10/site-packages/nbclient/client.py", line 862, in _check_raise_for_error
    raise CellExecutionError.from_cell_and_msg(cell, exec_reply_content)
nbclient.exceptions.CellExecutionError: An error occurred while executing the following cell:
------------------
# pathline solution
from scipy.integrate import solve_ivp
path0 = solve_ivp(vxvy, (0, tmax), y0=[-200, 50], t_eval=t, events=reached_well)
print('path0 message:', path0.message)
print(f'path0 reached well after {path0.t_events[0][0] / 365: .2f} years')
print(f'path0 entered well screen at', path0.y_events)
path1 = solve_ivp(vxvy, (0, tmax), y0=[-200, 80], t_eval=t, events=reached_well)
print('path1 message:', path1.message)
------------------

[0;31m---------------------------------------------------------------------------[0m
[0;31mModuleNotFoundError[0m                       Traceback (most recent call last)
Input [0;32mIn [7][0m, in [0;36m<cell line: 2>[0;34m()[0m
[1;32m      1[0m [38;5;66;03m# pathline solution[39;00m
[0;32m----> 2[0m [38;5;28;01mfrom[39;00m [38;5;21;01mscipy[39;00m[38;5;21;01m.[39;00m[38;5;21;01mintegrate[39;00m [38;5;28;01mimport[39;00m solve_ivp
[1;32m      3[0m path0 [38;5;241m=[39m solve_ivp(vxvy, ([38;5;241m0[39m, tmax), y0[38;5;241m=[39m[[38;5;241m-[39m[38;5;241m200[39m, [38;5;241m50[39m], t_eval[38;5;241m=[39mt, events[38;5;241m=[39mreached_well)
[1;32m      4[0m [38;5;28mprint[39m([38;5;124m'[39m[38;5;124mpath0 message:[39m[38;5;124m'[39m, path0[38;5;241m.[39mmessage)

[0;31mModuleNotFoundError[0m: No module named 'scipy'
ModuleNotFoundError: No module named 'scipy'

